Ошибка с моей стороны при работе бота

Traceback (most recent call last):
  File "/home/ekaterina/PycharmProjects/testVk_Bot/main.py", line 52, in <module>
    send_message(user_id, 'Привет, для поиска пары введи: пол, возраст от и до, город', keyboard)
  File "/home/ekaterina/PycharmProjects/testVk_Bot/main.py", line 22, in send_message
    session.method('messages.send', post)
  File "/home/ekaterina/PycharmProjects/testVk_Bot/venv/lib/python3.8/site-packages/vk_api/vk_api.py", line 697, in method
    raise error
vk_api.exceptions.ApiError: [901] Can't send messages for users without permission

Ищу причину и не могу найти, еще завтра попробую добавить кого-нибудь в группу и написать ему сообщение. Ну или просить помощи у кураторов. (Не знаю, может это быть как-то связано с тем, что я не в России)

Твой вариант с users.search для поиска пары намного лучше чем users.get, как было у меня. Только у меня предложение использовать класс для параметров на выходе

Т.к. я не могу нормально тестировать общение с ботом, вот предложения по тому, что я могу сделать в ближайщее время:

#модуль с БД запросами +
#search_possible_pair c большим количеством параметров на выходе для БД +
#создать классы для работы с параметрами на выходе, так легче потом записать в базу данных +
(для работы с твоим кодом я могу использовать отдельную branch и потом с main ее можно будет соединить)

И вот примерные остальные задачи:

#функционал для кнопки next: считывает последующих пользователей из БД, а когда они заканчиваются, нужно спросить пользователя, загружать ли еще?
#фавориты
#черный список
#предусмотреть возможные исключения
